Workbook

Sheet CALCULATIONS
F2: Beige background = user editable | J2: STEP 2 Your weight change goal
B3: STEP 1 Enter your current body stats | J3: Calculate goal weight change | P3: Enable | AY3: Current goal available | BA3: Main goal | BD3: variables | BF3: variables
B4: Body Stats | J4: 1) What is your current training experience? | AY4: =if(or(AW10=1,and(AW8=2,or(AW10=2,AW10=2,AW10=3,AW10=4))),"Cut (Calorie Deficit)","") | AZ4: 1 | BA4: Build Muscle | BB4: 1 | BD4: =IF($G$5="Lb",1,2) -> 2 | BF4: =IF($G$5="Lb",1,2) -> 2
B5: Weights in Lb or Kg? | J5: - Beginner (less than 1 year of consistent training/dieting) | AS5: Sex | AW5: =G9 | AY5: =if(or(AW8=3),"Maintain ","") | AZ5: 2 | BA5: Lose Fat | BB5: 2 | BD5: =3 -> 3 | BF5: =3 -> 3
B6: 1) Enter your starting date (double-click to select calendar) | J6: - Intermediate (more than 1 year of consistent training/dieting) | AJ6: initial BF% calc | AL6: =if($G16="","", if(and($G$9="Male",count($G$15:$G$17)=3), round(if($G16="","", if($G$14="cm",86.01*log($G16-$G17)-70.041*log($G$15)+30.3, if($G$14="inch",86.01*log(($G16-$G17)*2.54)-70.041*log($G$15*2.54)+30.3))),0), if( and($G$9="Female",count($G$15:$G$18)=4), round(if($G16="","", if($G$14="cm",495/(1.29579-0.35004*log10($G16+$G18-$G17)+0.221 * log10($G$15))-450, if($G$14="inch",495/(1.29579-0.35004*log10(($G16+$G18-$G17)*2.54)+0.221*log10($G$15*2.54))-450))),0)))) | AM6: =if(isnumber(AL6),if(AL6>1,AL6,""),"") | AS6: BF% | AW6: =BY15 | AY6: =if(and(AW8=1,or(AW10=2,AW10=3,AW10=4)),"Lean Bulk (Calorie Surplus) ","") | AZ6: 3 | BA6: Maintain | BB6: 3 | BD6: =SUM(BD4:BD5) -> 5 | BF6: =SUM(BF4:BF5) -> 5
B7: 2) Enter your current weight * | H7: =if($G$5="Lb","lbs",if($G$5="Kg","Kgs","")) | J7: 2) What is your MAIN goal right now? | AJ7: BF% calc warning | AL7: =if(and($G$13="Enable",or(count($G$15:$G$17)<>3,$G$14="")),"Warning: Please fill out all steps 3-5 above or disable",if(and($G$19="",$G$13="Enable",count($G$15:$G$17)=3),"Error in BF% Calculation. Check entered values","")) | AS7: Training Experience | AW7: =P4 | AY7: =if(and(AW10=2,AW7="Beginner"),"Recomp ","") | AZ7: 4 | BD7: =IF(BD6=4,BF36,IF(BD6=5,BG36,IF(BD6=6,BH36,IF(BD6=7,BI36,"")))) -> 7716.17 | BF7: =IF(BF6=4,BF37,IF(BF6=5,BG37,IF(BF6=6,BH37,IF(BF6=7,BI37,"")))) -> 28.66006 | BO7: Activate new calc | BQ7: TRUE
B8: 3) Enter your estimated body fat (%) * | H8: % | J8: =AW11 | AS8: Main goal | AW8: =if(P7=BA4,BB4,if(P7=BA5,BB5,if(P7=BA6,BB6,if(P7=BA7,BB7,0))))
B9: 4) Enter your Gender * | AS9: Current selected recommended goal | AW9: =if(AW8<>"",if(P11=AY4,AZ4,if(P11=AY5,AZ5,if(P11=AY6,AZ6,if(P11=AY7,AZ7,0)))),"")
B10: =if(or(count($G$7:$G$8)<>2,$G$9=""),"Please fill out all items 1-4 above",if(and(count($G$7:$G$8)=2,$G$9<>""),"Warning: After inputting, please DON'T update items 2 and 3 above.","")) -> Please fill out all items 1-4 above | J10: =BC10 | AS10: Goal Category | AW10: =if(AW5="Male", if(AW8=3,0, if(AW6>=20, 1, if(AW6>15, 2, if(AW6>12, 3,4)))), if(AW5="Female", if(AW8=3,0, if(AW6>=30,1, if(AW6>25,2, if(AW6>22,3,4)))),0)) -> 0 | AY10: Old Goal Category | BB10: =if(AW5="Male", if(AW8=3,0, if(BY21>=20, 1, if(BY21>15, 2, if(BY21>12, 3,4)))), if(AW5="Female", if(AW8=3,0, if(BY21>=30,1, if(BY21>25,2, if(BY21>22,3,4)))),0)) -> 0 | BC10: =if(AND(BB10<>AW10,AW9=0), "BF% Has changed and your recommended phase needs to be updated","")
J11: 3) Here is the phase we recommend for you: | U11: * Select your phase from recommended list | AS11: Message | AW11: =if(AW8="","",CONCATENATE("Based on your BF% and goal we suggest that you ", AY4, if(and(ne(AY4,""),or(ne(AY5,""),ne(AY6,""),ne(AY7,""))), " or ", ""), AY5, if(and(ne(AY5,""),or(ne(AY6,""),ne(AY7,""))), " or ", ""), AY6, if(and(ne(AY6,""),ne(AY7,"")), " or ", ""),AY7))
J12: Your suggested goal weight change per week is: | P12: =$AW14 | Q12: =if($G$5="Lb","lbs",if($G$5="Kg","Kgs","")) | AX12: Male | AY12: Female
B13: OPTIONAL Calculate your body fat % | G13: Disable | J13: This is the recommended weight change per week based on your training experience, body fat % and goal. If you want a different goal weight change, disable the "calculate goal weight change" and "enter goal weight change" in item 4 below | AB13: 2) Enter your current weight * | AE13: =G7 | AF13: =if($G$5="Lb","lbs","Kgs") -> Kgs | AG13: =if(E38="",AE13,E38) | AS13: Calculate Weight change% | AW13: =if(AW5="Male", AX13, if(AW5="Female", AY13, 0)) -> 0 | AX13: =if(AW7="Beginner", if(AW9=2,0, if(AW6>=20, -0.7, if(AW6>15, if(AW9=3,1.5/4, if(AW9=1,-0.7,0)), if(AW6>12, if(AW9=3,1.5/4, if(AW9=1,-0.5,0)), if(AW6<=12, if(AW9=3,1.5/4, if(AW9=1,-0.3,0)),0))))), if(AW7="Intermediate", if(AW9=2,0, if(AW6>=20, -0.7, if(AW6>15, if(AW9=3,1/4, if(AW9=1,-0.7,0)), if(AW6>12, if(AW9=3,1/4, if(AW9=1,-0.5,0)), if(AW6<=12, if(AW9=3,1/4, if(AW9=1,-0.3,0)),0))))),0)) -> 0 | AY13: =if(AW7="Beginner", if(AW9=2,0, if(AW6>=30, -0.7, if(AW6>25, if(AW9=3,1/4, if(AW9=1,-0.7,0)), if(AW6>22, if(AW9=3,1/4, if(AW9=1,-0.5,0)), if(AW6<=22, if(AW9=3,1/4, if(AW9=1,-0.3,0)),0))))), if(AW7="Intermediate", if(AW9=2,0, if(AW6>=30, -0.7, if(AW6>25, if(AW9=3,0.5/4, if(AW9=1,-0.7,0)), if(AW6>22, if(AW9=3,0.5/4, if(AW9=1,-0.5,0)), if(AW6<=22, if(AW9=3,0.5/4, if(AW9=1,-0.3,0)),0))))),0)) -> 0 | BO13: Old Protein Calc | BT13: New Dynamic Calculation of Protein
B14: Step 1: Measurements in cm/in? | AS14: Calculated Weight loss goal | AW14: =if(and(P3="Enable",P3<>"",P4<>"",P11<>"",P7<>""),if(AW9=4,if(G5="Lbs",-0.5,-0.227),(AW13/100)*BY14),"") | BC14: Male/Female Macro calc variables | BO14: =if(BD24=FALSE,"",G7*$BD$18) | BT14: Latest Weight | BY14: =IFERROR(__xludf.DUMMYFUNCTION("if(count($BO36:$BO140)>0,index(filter($BO36:$BO140,$BO36:$BO140 <>""""),count($BO36:$BO140)),G7)"),"")
B15: Step 2: Enter your Height: | H15: =IF($G$14="Inch","in",IF($G$14="cm","cm","")) | AS15: Used weight loss goal | AW15: =if(P3="Enable",AW14,Q16) | BC15: gender TDEE multiplier | BD15: =if($BD$24=TRUE,if($G$9="Male",1.5,if($G$9="Female",1.55,"")),"") | BO15: =if(BD24=FALSE,"",round($G$7*$BD$16,0)& " - " &round($G$7*$BD17,0)) | BT15: Latest BF% | BY15: =if(count(BT$36:BT140)>0,$BT$141,$G$8)
B16: Step 3: Enter your Waist Measurement: | H16: =IF($G$14="Inch","in",IF($G$14="cm","cm","")) | J16: =concatenate("4) Enter your goal weight change per week (-/+ ",G5,") if you want a different goal than recommended above") -> 4) Enter your goal weight change per week (-/+ ) if you want a different goal than recommended above | R16: =if($G$5="Lb","lbs",if($G$5="Kg","Kgs","")) | U16: * Manually enter your goal weight when above is disabled | BC16: lower protein multiplier | BD16: =if($BD$24=TRUE,if($G$9="Male",if(and($G$5="lb",$G$8<20),0.8,if(and($G$5="lb",$G$8>=20),0.73,if(and($G$5="kg",$G$8<20),1.76,if(and($G$5="kg",$G$8>=20),1.606)))),if($G$5="lb",0.8,1.7778)),"") | BT16: Latest Protein Multiplier | BY16: =IFERROR(__xludf.DUMMYFUNCTION("if(count(BV$36:BV140)>0,index(filter(BV$36:BV140,BV$36:BV140 <>""""),count(BV$36:BV140)),$BD$18)"),"")
B17: Step 4: Enter Your Neck Measurement: | H17: =IF($G$14="Inch","in",IF($G$14="cm","cm","")) | AS17: Calorie Surplus | AW17: =if(BD24=FALSE,"",if(G5="lb",((AW15*3500)/7),if(G5="Kg",((AW15*7700)/7),""))) | BC17: upper protein mutiplier | BD17: =if($BD$24=TRUE,if($G$9="Male",if(and($G$5="lb",$G$8<20),1.2,if(and($G$5="lb",$G$8>=20),1,if(and($G$5="kg",$G$8<20),2.64,if(and($G$5="kg",$G$8>=20),2.2)))),if($G$5="lb",1.2,2.6667)),"") | BT17: Latest Recommended Protein Amount | BY17: =IFERROR(__xludf.DUMMYFUNCTION("if(count(BW$36:BW140)>0,index(filter(BW$36:BW140,BW$36:BW140 <>""""),count(BW$36:BW140)),$G$7)"),"")
B18: =if($G$9="Male","",if($G$9="Female","Step 6: Enter your Hip Measurement:","")) | H18: =if($G$9="Male","",if(and($G$9="Female",$G$14="cm"),"cm",if(and($G$9="Female",$G$14="inch"),"in",""))) | J18: STEP 3 Your TDEE and macronutrient requirements | AS18: Calculated TDEE | AW18: =IFERROR(__xludf.DUMMYFUNCTION("if(count($G$7:$G$9)<>2,"""",if(count($U$36:$U141)>3,index(filter($U$36:$U141,$U$36:$U141<>""""),count($U$36:$U141)-1,1),if(G5=""Lb"",(370 + (9.8*($G$7*((100-$AW$6) / 100)) )) * $BD$15,(370 + (21.6*($G$7*((100-$AW$6) / 100)) )) * $BD$15)))"),"") | BC18: recommended protein multiplier | BD18: =if($BD$24=TRUE, if($G$9="Male", if(and($G$5="lb",$G$8<20),1, if(and($G$5="lb",$G$8>=20,$G$8<=25),0.8, if(and($G$5="lb",$G$8>25),0.73, if(and($G$5="kg",$G$8<20),2.2, if(and($G$5="kg",$G$8>=20,$G$8<=25),1.76, if(and($G$5="kg",$G$8>25),1.606)))))), if($G$5="lb",0.8,1.7778)),"") | BT18: Latest Minimum Protein Amount | BY18: =IFERROR(__xludf.DUMMYFUNCTION("if(count(BZ$36:BZ140)>0,index(filter(BZ$36:BZ140,BZ$36:BZ140 <>""""),count(BZ$36:BZ140)),$G$7)"),0.0) -> 0
B19: Your Calculated BF% is: | G19: =AM6 | H19: % | AS19: need to eat | AW19: =if(BD24=FALSE,"",max($BD$22,$AW$17+$AW$18)) | BC19: lower fat multiplier | BD19: =if($BD$24=TRUE,if($G$9="Male",0.15,0.2),"") | BT19: Latest Maximum Protein Amount | BY19: =IFERROR(__xludf.DUMMYFUNCTION("if(count(CA$36:CA140)>0,index(filter(CA$36:CA140,CA$36:CA140 <>""""),count(CA$36:CA140)),$G$7)"),0.0) -> 0
B20: =$AL$7 | J20: Your Estimated Current TDEE is | Q20: =IFERROR(__xludf.DUMMYFUNCTION("if(and($BD$24=TRUE,or(and($P$3=""Enable"",P4<>"""",P7<>"""",P11<>""""),P3=""Disable"")),if(count($U$36:$U141)>3, index(filter($U$36:$U141,$U$36:$U141<>""""),count($U$36:$U141)-1,1), if(G5=""Lb"&""", (370 + (9.8*($G$7*((100-$BY$15) / 100)) )) * $BD$15, (370 + (21.6*($G$7*((100-$BY$15) / 100)) )) * $BD$15)),"""")"),"") | R20: calories | AG20: avg daily calories + ((-prev week differential*3500)/# of days logged) | AM20: base tdee formula | AN20: =if(G5="Lb",(370 + (9.8*($G$7*((100-$G$18) / 100)) )) * 1.5,(370 + (21.6*($G$7*((100-$G$18) / 100)) )) * 1.5) -> 555 | AS20: protein | AW20: =IF(BD24,BO22,"") | BC20: upper fat multiplier | BD20: =if($BD$24=TRUE,if($G$9="Male",0.3,0.4),"") | BT20: Latest Protein Range | BY20: =if(BD24=FALSE,"",round(BY18,0)& " - " &round(BY19,0))
AD21: =2050+((-3*3500)) -> -8450 | AM21: old formula: =MROUND(G7*BB7,5) | AN21: =G7*BF7 -> 0 | AS21: fat | AW21: =if(BD24,+(($BD$21*$Q$25)/9),"") | BC21: recommended fat multiplier | BD21: =if($BD$24=TRUE, if($G$9="Male", if($BY$15<25, 0.22, if($BY$15>=25,0.25,0)), if($G$9="Female",0.3,"")),"") | BO21: Active Calc | BT21: Previous BF% | BY21: =if(count(BT$36:BT140)>0,$BU$141,$G$8)
B22: Reminder: Do NOT eat back your calories from extra exercise. The nutrition tracking spreadsheet already takes this into account. See the FAQ for more information | J22: =IF(Q22<0,"Your Target Daily Deficit","Your Target Daily Surplus") -> Your Target Daily Surplus | Q22: =if(or(BD24=FALSE,AW15=""),"",if(G5="lb",((AW15*3500)/7),if(G5="Kg",((AW15*7700)/7),""))) | R22: calories | AM22: new formula (with body fat) | AN22: =if(G5="Lb",(370 + (9.8*($G$7*((100-if($G$13="Enable",$G$18,$G$8)) / 100)) )) * $BD$15,(370 + (21.6*($G$7*((100-if($G$13="Enable",$G$18,$G$8)) / 100)) )) * $BD$15) -> 0 | AS22: carbs | AW22: =if(BD24,($Q$25-($Q$26*4)-($Q$27*9))/4,"") | BC22: lower calorie limit | BD22: =if($BD$24=TRUE,if($G$9="Male",1500,1200),"") | BO22: =if(BQ7,BY17,BO14)
AS23: Calorie message | AW23: =if(and(BD24,$AW$17+$AW$18<$BD$22),"Calculated calories have been set to the minimum. See FAQ","") | BO23: =if(BQ7,BY20,BO15)
J24: Here are Your Daily Calories/Macros: | BC24: all required fields entered | BD24: =if( and( or($G$5="Kg",$G$5="Lb"), $G$7<>"", $G$9<>"", or($G$8<>"", and($G$13="Enable",$G$19<>"")) , or(and(P3="Enable"), and( if(isblank(Q16)=FALSE,true,false),P3="Disable"))),true, false) -> FALSE
J25: You need to eat: | Q25: =if(or(BD24=FALSE,AW15=""),"",max($BD$22,$Q$20+$Q$22)) | R25: calories | S25: Acceptable Range* | AV25: current estimated | AW25: =if(G5="Lb",(370 + (9.8*($G$7*((100-if($G$13="Enable",$G$18,$G$8)) / 100)) )) * $BD$15,(370 + (21.6*($G$7*((100-if($G$13="Enable",$G$18,$G$8)) / 100)) )) * $BD$15) -> 0
J26: You need this many grams of protein: | Q26: =IF(or(BD24=FALSE,AW15=""),"",BO22) | R26: grams | S26: =if(or(BD24=FALSE,AW15=""),"",BO23) | AV26: current day to day | AW26: =IF(AL36=0,$AN$22,IF(AL37=0,$AN$22,AW37+(((-AZ36)*$BD$7)/AL37))) -> 0
B27: =if(count(AC39:AC46)<4,concatenate("Reminder:"," Your calories, protein, fat & carbs will start adjusting by the beginning of week 4. "," Until then stick with your initial calories/macros values."),"") -> Reminder: Your calories, protein, fat & carbs will start adjusting by the beginning of week 4. Until then stick with your initial calories/macros values. | J27: You need this many grams of fat: | Q27: =if(or(BD24=FALSE,AW15=""),"",+(($BD$21*$Q$25)/9)) | R27: grams | S27: =if(or(BD24=FALSE,AW15=""),"",round(($BD$19*$Q$25)/9,0) & " - " & round(($BD$20*$Q$25)/9,0))
J28: You need this many grams of carbs: | Q28: =if(or(BD24=FALSE,AW15=""),"",($Q$25-($Q$26*4)-($Q$27*9))/4) | R28: grams | S28: =if(or(BD24=FALSE,AW15=""),"",round($Q$28*0.8,0)& " - " &round($Q$28*1.2,0))
AU29: highlight min/max | AW29: =if(AW15=0,FALSE,TRUE) -> TRUE
J30: =$AW$23 | AU30: highlight value | AW30: =if(AW15<0,min($E$36:$K$36,$E$38:$K$38,$E$40:$K$40,$E$42:$K$42,$E$44:$K$44,$E$46:$K$46,$E$48:$K$48,$E$50:$K$50,$E$52:$K$52,$E$54:$K$54,$E$56:$K$56,$E$58:$K$58,$E$60:$K$60,$E$62:$K$62,$E$64:$K$64,$E$66:$K$66,$E$68:$K$68,$E$70:$K$70,$E$72:$K$72,$E$74:$K$74,$E$76:$K$76,$E$78:$K$78,$E$80:$K$80,$E$82:$K$82,$E$84:$K$84,$E$86:$K$86,$E$88:$K$88,$E$90:$K$90,$E$92:$K$92,$E$94:$K$94,$E$96:$K$96,$E$98:$K$98,$E$100:$K$100,$E$102:$K$102,$E$104:$K$104,$E$106:$K$106,$E$108:$K$108,$E$110:$K$110,$E$112:$K$112,$E$114:$K$114,$E$116:$K$116,$E$118:$K$118,$E$120:$K$120,$E$122:$K$122,$E$124:$K$124,$E$126:$K$126,$E$128:$K$128,$E$130:$K$130,$E$132:$K$132,$E$134:$K$134,$E$136:$K$136,$E$138:$K$138,$E$140:$K$140),if(AW15>0,max($E$36:$K$36,$E$38:$K$38,$E$40:$K$40,$E$42:$K$42,$E$44:$K$44,$E$46:$K$46,$E$48:$K$48,$E$50:$K$50,$E$52:$K$52,$E$54:$K$54,$E$56:$K$56,$E$58:$K$58,$E$60:$K$60,$E$62:$K$62,$E$64:$K$64,$E$66:$K$66,$E$68:$K$68,$E$70:$K$70,$E$72:$K$72,$E$74:$K$74,$E$76:$K$76,$E$78:$K$78,$E$80:$K$80,$E$82:$K$82,$E$84:$K$84,$E$86:$K$86,$E$88:$K$88,$E$90:$K$90,$E$92:$K$92,$E$94:$K$94,$E$96:$K$96,$E$98:$K$98,$E$100:$K$100,$E$102:$K$102,$E$104:$K$104,$E$106:$K$106,$E$108:$K$108,$E$110:$K$110,$E$112:$K$112,$E$114:$K$114,$E$116:$K$116,$E$118:$K$118,$E$120:$K$120,$E$122:$K$122,$E$124:$K$124,$E$126:$K$126,$E$128:$K$128,$E$130:$K$130,$E$132:$K$132,$E$134:$K$134,$E$136:$K$136,$E$138:$K$138,$E$140:$K$140))) -> 0
B31: STEP 4 Enter you calorie intake and weight (daily) | AU31: highlight average value | AW31: =if(AW15<0,AX35,if(AW15>0,AY35)) -> 0
AL33: current | AM33: goal | AX33: MIN | AY33: MAX | BD33: units/conversions
B34: Week | D34: Stats | E34: =text($G$6,"ddd") -> Sat | F34: =text($G$6+1,"ddd") -> Sun | G34: =text($G$6+2,"ddd") -> Mon | H34: =text($G$6+3,"ddd") -> Tue | I34: =text($G$6+4,"ddd") -> Wed | J34: =text($G$6+5,"ddd") -> Thu | K34: =text($G$6+6,"ddd") -> Fri | L34: Avg. | N34: waist | O34: neck | P34: hip | Q34: Calculated BF% | R34: Estimated BF% | S34: Weight Change | U34: TDEE | W34: Current Entry? | X34: week | Y34: Month | AX34: =MIN(AW36,AW38,AW40,AW42,AW44,AW46,AW48,AW50,AW52,AW54,AW56,AW58,AW60,AW62,AW64,AW66,AW68,AW70,AW72,AW74,AW76,AW78,AW80,AW82,AW84,AW86,AW88,AW90,AW92,AW94,AW96,AW98,AW100,AW102,AW104,AW106,AW108,AW110,AW112,AW114,AW116,AW118,AW120,AW122,AW124,AW126,AW128,AW130,AW132,AW134,AW136,AW138,AW140) -> 0 | AY34: =MAX(AW36,AW38,AW40,AW42,AW44,AW46,AW48,AW50,AW52,AW54,AW56,AW58,AW60,AW62,AW64,AW66,AW68,AW70,AW72,AW74,AW76,AW78,AW80,AW82,AW84,AW86,AW88,AW90,AW92,AW94,AW96,AW98,AW100,AW102,AW104,AW106,AW108,AW110,AW112,AW114,AW116,AW118,AW120,AW122,AW124,AW126,AW128,AW130,AW132,AW134,AW136,AW138,AW140) -> 0 | BR34: BF% History | BZ34: Protein Amount
N35: =if($G$15="","Enter your height in Step 1 to calculate body fat","") -> Enter your height in Step 1 to calculate body fat | AB35: =today() -> 46183 | AL35: row count | AM35: =G7 | AW35: avg daily weight/ avg daily calories | AX35: =MAX(AX36:AX141) -> 0 | AY35: =MAX(AY36:AY141) -> 0 | AZ35: prev week differntial | BA35: =max(BA36:BA141) -> 140 | BB35: =vlookup($BA$35,BA36:BB140,2,false) -> 11 | BC35: tdee | BD35: master TDEE calcs | BE35: weekly TDEE calcs | BF35: lb cal | BG35: kg cal | BH35: lb kj | BI35: kg kj | BJ35: YYYY - MMM | BL35: BF Calc | BO35: Average weight history | BQ35: Calc BF% | BR35: Est BF% | BS35: Used BF% | BV35: Protein Multiplier | BW35: Recommended Protein | BZ35: Min | CA35: Max
B36: =IF(G6="","",G6) | D36: Weight | L36: =if(counta(E36:K36)=0,"",AVERAGE(E36:K36)) | Q36: =BL36 | S36: =IF(L36="","",(L36-$G$7)) | U36: =if(BD$24=FALSE,"",IF(L36="","",BC36)) | W36: =IF(count(S36:S37)>1,1,0) -> 0 | X36: =if($Y$36="","","Week 1") | Y36: =IF(S36="","",text(B36,"MMM-YY")) | AB36: =B36 | AC36: =AB36 | AD36: =AC36+1 -> 1 | AE36: =AD36+1 -> 2 | AF36: =AE36+1 -> 3 | AG36: =AF36+1 -> 4 | AH36: =AG36+1 -> 5 | AI36: =AH36+1 -> 6 | AJ36: 1 | AL36: =COUNT(AP36:AV36) -> 0 | AM36: =IF(AW36="",AM35,L36) | AP36: =IF(COUNT($E36:$K36)<1,"",IF(E36="",$G$7,E36)) | AQ36: =IF(F36="",AP36,F36) | AR36: =IF(G36="",AQ36,G36) | AS36: =IF(H36="",AR36,H36) | AT36: =IF(I36="",AS36,I36) | AU36: =IF(J36="",AT36,J36) | AV36: =IF(K36="",AU36,K36) | AW36: =IF(AL36=0,$G$7,average(AP36:AV36)) | AX36: =if(AND(AW36=AX$34,$AL36>0),ROW(),0) -> 0 | AY36: =if(AND(AW36=AY$34,$AL36>0),ROW(),0) -> 0 | AZ36: =IF(AW36="","",AW36-$G$7) | BA36: =if(BB36>0,row(),0) -> 36 | BB36: =max(if(E36=AW$30,COLUMN(E36),0),if(F36=AW$30,COLUMN(F36),0),if(G36=AW$30,COLUMN(G36),0),if(H36=AW$30,COLUMN(H36),0),if(I36=AW$30,COLUMN(I36),0),if(J36=AW$30,COLUMN(J36),0),if(K36=AW$30,COLUMN(K36),0)) -> 11 | BC36: =IF(BD36="","",IF(AZ36="","",BD36)) | BD36: =IF(AL36=0,$AN$22,IF(AL37=0,$AN$22,AW37+(((-AZ36)*$BD$7)/AL37))) -> 0 | BE36: =IF(AL36=0,$AN$22,AW37+(((-AZ36)*$BD$7)/AL37)) -> 0 | BF36: 3500 | BG36: =BF36*2.20462 -> 7716.17 | BH36: =BF36*4.184 -> 14644 | BI36: =BG36*4.184 -> 32284.455 | BJ36: =text(B36,"YYYY MMM") | BL36: =if($G$13="Disable","", if($G$9="","",if(and($G$9="Male",count($N36:$O36)<>2),"", if(and($G$9="Male",count($N36:$O36)=2),round(if($N36="","", if($G$14="cm",86.01*log($N36-$O36)-70.041*log($G$15)+30.3, if($G$14="inch",86.01*log(($N36-$O36)*2.54)-70.041*log($G$15*2.54)+30.3))),0), if(and($G$9="Female",count($N36:$P36)<>3),"", if(and($G$9="Female",count($N36:$P36)=3),round(if($N36="","", if($G$14="cm",495/(1.29579-0.35004*log10($N36+$P36-$O36)+0.221 * log10($G$15))-450, if($G$14="inch",495/(1.29579-0.35004*log10(($N36+$P36-$O36)*2.54)+0.221 * log10($G$15*2.54))-450))),0))))))) | BO36: =IFERROR(__xludf.DUMMYFUNCTION("filter($L$36:$L141,$D$36:$D141<>"""",$D$36:$D141=""Weight"")"),"") | BP36: =$G$7 | BQ36: =IFERROR(__xludf.DUMMYFUNCTION("filter($Q$36:$Q141,$D$36:$D141=""Weight"")"),"") | BR36: =IFERROR(__xludf.DUMMYFUNCTION("filter($R$36:$R141,$D$36:$D141=""Weight"")"),"") | BS36: =if($G$13="Enable",if(BQ36<>"",BQ36,BR36),if(BR36<>"",BR36,BQ36)) | BT36: =if(and($G$13="Enable",$G$19<>""),$G$19,$G$8) | BV36: =if($BP36<>"", if($G$9="Male", if(and($G$5="lb",$BT36<20),1, if(and($G$5="lb",$BT36>=20,$BT36<=25),0.8, if(and($G$5="lb",$BT36>25),0.73, if(and($G$5="kg",$BT36<20),2.2, if(and($G$5="kg",$BT36>=20,$BT36<=25),1.76, if(and($G$5="kg",$BT36>25),1.606)))))), if($G$9="Female", if(and($G$5="lb",$BT36<=25),1, if(and($G$5="lb",$BT36>25),0.8, if(and($G$5="kg",$BT36<=25),2.2, if(and($G$5="kg",$BT36>25),1.76,"")))),""))) -> FALSE | BW36: =if($BP36<>"",$BP36*BV36,"") | BX36: =if($BP36<>"", if($G$9="Male", if(and($G$5="lb",$BT36<20),0.8, if(and($G$5="lb",$BT36>=20),0.73, if(and($G$5="kg",$BT36<20),1.76, if(and($G$5="kg",$BT36>=20),1.606)))), if($G$9="Female", if($G$5="lb",0.8,1.76),""))) -> FALSE | BY36: =if($BP36<>"", if($G$9="Male", if(and($G$5="lb",$BT36<20),1.2, if(and($G$5="lb",$BT36>=20),1, if(and($G$5="kg",$BT36<20),2.64, if(and($G$5="kg",$BT36>=20),2.2)))), if($G$9="Female", if($G$5="lb",1.4,3.08),""))) -> FALSE | BZ36: =BP36*BX36 -> 0 | CA36: =BP36*BY36 -> 0
D37: Calories | L37: =if(counta(E37:K37)=0,"",AVERAGE(E37:K37)) | X37: =if($Y$36="","","Week 1") | AB37: =B38 | AC37: =AB37 | AD37: =AC37+1 -> 1 | AE37: =AD37+1 -> 2 | AF37: =AE37+1 -> 3 | AG37: =AF37+1 -> 4 | AH37: =AG37+1 -> 5 | AI37: =AH37+1 -> 6 | AJ37: =AJ36+0.5 -> 1.5 | AL37: =COUNT(AP37:AV37) -> 0 | AM37: =AM36 | AP37: =IF(COUNT($E37:$K37)<1,"",IF(E37="",AQ31,E37)) | AQ37: =IF(F37="",AP37,F37) | AR37: =IF(G37="",AQ37,G37) | AS37: =IF(H37="",AR37,H37) | AT37: =IF(I37="",AS37,I37) | AU37: =IF(J37="",AT37,J37) | AV37: =IF(K37="",AU37,K37) | AW37: =IF(AL37=0,"",average(AP37:AV37)) | BF37: 13 | BG37: =BF37*2.20462 -> 28.66006 | BH37: =BF37*4.184 -> 54.392 | BI37: =BG37*4.184 -> 119.91369 | BO37: =IFERROR(__xludf.DUMMYFUNCTION("""COMPUTED_VALUE"""),"") | BP37: =$G$7 | BQ37: =IFERROR(__xludf.DUMMYFUNCTION("""COMPUTED_VALUE"""),"") | BS37: =if($G$13="Enable",if(BQ37<>"",BQ37,BR37),if(BR37<>"",BR37,BQ37)) | BT37: =if(and($G$13="Enable",$G$19<>""),$G$19,$G$8) | BU37: =BT36 | BV37: =if($BP37<>"", if($G$9="Male", if(and($G$5="lb",$BT37<20),1, if(and($G$5="lb",$BT37>=20,$BT37<=25),0.8, if(and($G$5="lb",$BT37>25),0.73, if(and($G$5="kg",$BT37<20),2.2, if(and($G$5="kg",$BT37>=20,$BT37<=25),1.76, if(and($G$5="kg",$BT37>25),1.606)))))), if($G$9="Female", if(and($G$5="lb",$BT37<=25),1, if(and($G$5="lb",$BT37>25),0.8, if(and($G$5="kg",$BT37<=25),2.2, if(and($G$5="kg",$BT37>25),1.76,"")))),""))) -> FALSE | BW37: =if($BP37<>"",$BP37*BV37,"") | BX37: =if($BP37<>"", if($G$9="Male", if(and($G$5="lb",$BT37<20),0.8, if(and($G$5="lb",$BT37>=20),0.73, if(and($G$5="kg",$BT37<20),1.76, if(and($G$5="kg",$BT37>=20),1.606)))), if($G$9="Female", if($G$5="lb",0.8,1.76),""))) -> FALSE | BY37: =if($BP37<>"", if($G$9="Male", if(and($G$5="lb",$BT37<20),1.2, if(and($G$5="lb",$BT37>=20),1, if(and($G$5="kg",$BT37<20),2.64, if(and($G$5="kg",$BT37>=20),2.2)))), if($G$9="Female", if($G$5="lb",1.4,3.08),""))) -> FALSE | BZ37: =if(BW37<>BW36,BP37*BX37,BZ36) -> 0 | CA37: =if(BW37<>BW36,BP37*BY37,CA36) -> 0
B38: =IF(B36="","",B36+7) | D38: =D36 -> Weight | L38: =if(counta(E38:K38)=0,"",AVERAGE(E38:K38)) | Q38: =BL38 | S38: =IFERROR(__xludf.DUMMYFUNCTION("IF(L38="""","""",(L38-index(filter($L$36:L36,$L$36:L36<>"""",ISEVEN(row($L$36:L36))),count(filter($L$36:L36,$L$36:L36<>"""",iseven(row($L$36:L36)))),1)))"),"") | U38: =if(BD$24=FALSE,"",IF(L38="","",BC38)) | W38: =IF(count(S38:S39)>1,1,0) -> 0 | X38: =if(Y38="","","Week 2") | Y38: =IF(S38="","",text(B38,"MMM-YY")) | AB38: =B40 | AC38: =AB38 | AD38: =AC38+1 -> 1 | AE38: =AD38+1 -> 2 | AF38: =AE38+1 -> 3 | AG38: =AF38+1 -> 4 | AH38: =AG38+1 -> 5 | AI38: =AH38+1 -> 6 | AJ38: =AJ36+1 -> 2 | AK38: 1 | AL38: =COUNT(AP38:AV38) -> 0 | AM38: =IF(K38="",AM36,K38) | AP38: =IF(COUNT($E38:$K38)<1,"",IF(E38="",AQ32,E38)) | AQ38: =IF(F38="",AP38,F38) | AR38: =IF(G38="",AQ38,G38) | AS38: =IF(H38="",AR38,H38) | AT38: =IF(I38="",AS38,I38) | AU38: =IF(J38="",AT38,J38) | AV38: =IF(K38="",AU38,K38) | AW38: =IF(AL38=0,AW36,average(AP38:AV38)) | AX38: =if(AND(AW38=AX$34,$AL38>0),ROW(),0) -> 0 | AY38: =if(AND(AW38=AY$34,$AL38>0),ROW(),0) -> 0 | AZ38: =IF(AW38="","",AW38-AW36) | BA38: =if(BB38>0,row(),0) -> 38 | BB38: =max(if(E38=AW$30,COLUMN(E38),0),if(F38=AW$30,COLUMN(F38),0),if(G38=AW$30,COLUMN(G38),0),if(H38=AW$30,COLUMN(H38),0),if(I38=AW$30,COLUMN(I38),0),if(J38=AW$30,COLUMN(J38),0),if(K38=AW$30,COLUMN(K38),0)) -> 11 | BC38: =IF(BD38="","",IF(AZ38="","",BD38)) | BD38: =IF(AL38=0,BD36,IF(AL39=0,BD36,AW39+(((-AZ38)*$BD$7)/AL39))) -> 0 | BE38: =IF(AL38=0,BE36,IF(AL39=0,BE36,AW39+(((-AZ38)*$BD$7)/AL39))) -> 0 | BJ38: =text(B38,"YYYY MMM") | BL38: =if($G$13="Disable","", if($G$9="","",if(and($G$9="Male",count($N38:$O38)<>2),"", if(and($G$9="Male",count($N38:$O38)=2),round(if($N38="","", if($G$14="cm",86.01*log($N38-$O38)-70.041*log($G$15)+30.3, if($G$14="inch",86.01*log(($N38-$O38)*2.54)-70.041*log($G$15*2.54)+30.3))),0), if(and($G$9="Female",count($N38:$P38)<>3),"", if(and($G$9="Female",count($N38:$P38)=3),round(if($N38="","", if($G$14="cm",495/(1.29579-0.35004*log10($N38+$P38-$O38)+0.221 * log10($G$15))-450, if($G$14="inch",495/(1.29579-0.35004*log10(($N38+$P38-$O38)*2.54)+0.221 * log10($G$15*2.54))-450))),0))))))) | BO38: =IFERROR(__xludf.DUMMYFUNCTION("""COMPUTED_VALUE"""),"") | BP38: =$G$7 | BQ38: =IFERROR(__xludf.DUMMYFUNCTION("""COMPUTED_VALUE"""),"") | BS38: =if($G$13="Enable",if(BQ38<>"",BQ38,BR38),if(BR38<>"",BR38,BQ38)) | BT38: =if(and($G$13="Enable",$G$19<>""),$G$19,$G$8) | BU38: =BT37 | BV38: =if($BP38<>"", if($G$9="Male", if(and($G$5="lb",$BT38<20),1, if(and($G$5="lb",$BT38>=20,$BT38<=25),0.8, if(and($G$5="lb",$BT38>25),0.73, if(and($G$5="kg",$BT38<20),2.2, if(and($G$5="kg",$BT38>=20,$BT38<=25),1.76, if(and($G$5="kg",$BT38>25),1.606)))))), if($G$9="Female", if(and($G$5="lb",$BT38<=25),1, if(and($G$5="lb",$BT38>25),0.8, if(and($G$5="kg",$BT38<=25),2.2, if(and($G$5="kg",$BT38>25),1.76,"")))),""))) -> FALSE | BW38: =if($BP38<>"",$BP38*BV38,"") | BX38: =if($BP38<>"", if($G$9="Male", if(and($G$5="lb",$BT38<20),0.8, if(and($G$5="lb",$BT38>=20),0.73, if(and($G$5="kg",$BT38<20),1.76, if(and($G$5="kg",$BT38>=20),1.606)))), if($G$9="Female", if($G$5="lb",0.8,1.76),""))) -> FALSE | BY38: =if($BP38<>"", if($G$9="Male", if(and($G$5="lb",$BT38<20),1.2, if(and($G$5="lb",$BT38>=20),1, if(and($G$5="kg",$BT38<20),2.64, if(and($G$5="kg",$BT38>=20),2.2)))), if($G$9="Female", if($G$5="lb",1.4,3.08),""))) -> FALSE | BZ38: =if(BW38<>BW37,BP38*BX38,BZ37) -> 0 | CA38: =if(BW38<>BW37,BP38*BY38,CA37) -> 0
D39: =D37 -> Calories | L39: =if(counta(E39:K39)=0,"",AVERAGE(E39:K39)) | AB39: =B42 | AC39: =AB39 | AD39: =AC39+1 -> 1 | AE39: =AD39+1 -> 2 | AF39: =AE39+1 -> 3 | AG39: =AF39+1 -> 4 | AH39: =AG39+1 -> 5 | AI39: =AH39+1 -> 6 | AJ39: =AJ38+0.5 -> 2.5 | AL39: =COUNT(AP39:AV39) -> 0 | AM39: =AM38 | AP39: =IF(COUNT($E39:$K39)<1,"",IF(E39="",AQ33,E39)) | AQ39: =IF(F39="",AP39,F39) | AR39: =IF(G39="",AQ39,G39) | AS39: =IF(H39="",AR39,H39) | AT39: =IF(I39="",AS39,I39) | AU39: =IF(J39="",AT39,J39) | AV39: =IF(K39="",AU39,K39) | AW39: =IF(AL39=0,AW37,average(AP39:AV39)) | BO39: =IFERROR(__xludf.DUMMYFUNCTION("""COMPUTED_VALUE"""),"") | BP39: =$G$7 | BQ39: =IFERROR(__xludf.DUMMYFUNCTION("""COMPUTED_VALUE"""),"") | BS39: =if($G$13="Enable",if(BQ39<>"",BQ39,BR39),if(BR39<>"",BR39,BQ39)) | BT39: =if(and($G$13="Enable",$G$19<>""),$G$19,$G$8) | BU39: =if(BS39="",BU38,BT38) | BV39: =if($BP39<>"", if($G$9="Male", if(and($G$5="lb",$BT39<20),1, if(and($G$5="lb",$BT39>=20,$BT39<=25),0.8, if(and($G$5="lb",$BT39>25),0.73, if(and($G$5="kg",$BT39<20),2.2, if(and($G$5="kg",$BT39>=20,$BT39<=25),1.76, if(and($G$5="kg",$BT39>25),1.606)))))), if($G$9="Female", if(and($G$5="lb",$BT39<=25),1, if(and($G$5="lb",$BT39>25),0.8, if(and($G$5="kg",$BT39<=25),2.2, if(and($G$5="kg",$BT39>25),1.76,"")))),""))) -> FALSE | BW39: =if($BP39<>"",$BP39*BV39,"") | BX39: =if($BP39<>"", if($G$9="Male", if(and($G$5="lb",$BT39<20),0.8, if(and($G$5="lb",$BT39>=20),0.73, if(and($G$5="kg",$BT39<20),1.76, if(and($G$5="kg",$BT39>=20),1.606)))), if($G$9="Female", if($G$5="lb",0.8,1.76),""))) -> FALSE | BY39: =if($BP39<>"", if($G$9="Male", if(and($G$5="lb",$BT39<20),1.2, if(and($G$5="lb",$BT39>=20),1, if(and($G$5="kg",$BT39<20),2.64, if(and($G$5="kg",$BT39>=20),2.2)))), if($G$9="Female", if($G$5="lb",1.4,3.08),""))) -> FALSE | BZ39: =if(BW39<>BW38,BP39*BX39,BZ38) -> 0 | CA39: =if(BW39<>BW38,BP39*BY39,CA38) -> 0
B40: =IF(B38="","",B38+7) | D40: =D38 -> Weight | L40: =if(counta(E40:K40)=0,"",AVERAGE(E40:K40)) | Q40: =BL40 | S40: =IFERROR(__xludf.DUMMYFUNCTION("IF(L40="""","""",(L40-index(filter($L$36:L38,$L$36:L38<>"""",ISEVEN(row($L$36:L38))),count(filter($L$36:L38,$L$36:L38<>"""",iseven(row($L$36:L38)))),1)))"),"") | U40: =if(BD$24=FALSE,"",IF(L40="","",BC40)) | W40: =IF(count(S40:S41)>1,1,0) -> 0 | X40: =if(Y40="","","Week 3") | Y40: =IF(S40="","",text(B40,"MMM-YY")) | AB40: =B44 | AC40: =AB40 | AD40: =AC40+1 -> 1 | AE40: =AD40+1 -> 2 | AF40: =AE40+1 -> 3 | AG40: =AF40+1 -> 4 | AH40: =AG40+1 -> 5 | AI40: =AH40+1 -> 6 | AJ40: =AJ38+1 -> 3 | AK40: 2 | AL40: =COUNT(AP40:AV40) -> 0 | AM40: =IF(K40="",AM38,K40) | AP40: =IF(COUNT($E40:$K40)<1,"",IF(E40="",AQ34,E40)) | AQ40: =IF(F40="",AP40,F40) | AR40: =IF(G40="",AQ40,G40) | AS40: =IF(H40="",AR40,H40) | AT40: =IF(I40="",AS40,I40) | AU40: =IF(J40="",AT40,J40) | AV40: =IF(K40="",AU40,K40) | AW40: =IF(AL40=0,AW38,average(AP40:AV40)) | AX40: =if(AND(AW40=AX$34,$AL40>0),ROW(),0) -> 0 | AY40: =if(AND(AW40=AY$34,$AL40>0),ROW(),0) -> 0 | AZ40: =IF(AW40="","",AW40-AW38) | BA40: =if(BB40>0,row(),0) -> 40 | BB40: =max(if(E40=AW$30,COLUMN(E40),0),if(F40=AW$30,COLUMN(F40),0),if(G40=AW$30,COLUMN(G40),0),if(H40=AW$30,COLUMN(H40),0),if(I40=AW$30,COLUMN(I40),0),if(J40=AW$30,COLUMN(J40),0),if(K40=AW$30,COLUMN(K40),0)) -> 11 | BC40: =IF(BD40="","",IF(AZ40="","",BD40)) | BD40: =IF(AL40=0,BD38,IF(AL41=0,BD38,((AW41+(((-AZ40)*$BD$7)/AL41)+sum($BE$38:BE38))/AK40))) -> 0 | BE40: =IF(AL40=0,BE38,IF(AL41=0,BE38,AW41+(((-AZ40)*$BD$7)/AL41))) -> 0 | BJ40: =text(B40,"YYYY MMM") | BL40: =if($G$13="Disable","", if($G$9="","",if(and($G$9="Male",count($N40:$O40)<>2),"", if(and($G$9="Male",count($N40:$O40)=2),round(if($N40="","", if($G$14="cm",86.01*log($N40-$O40)-70.041*log($G$15)+30.3, if($G$14="inch",86.01*log(($N40-$O40)*2.54)-70.041*log($G$15*2.54)+30.3))),0), if(and($G$9="Female",count($N40:$P40)<>3),"", if(and($G$9="Female",count($N40:$P40)=3),round(if($N40="","", if($G$14="cm",495/(1.29579-0.35004*log10($N40+$P40-$O40)+0.221 * log10($G$15))-450, if($G$14="inch",495/(1.29579-0.35004*log10(($N40+$P40-$O40)*2.54)+0.221 * log10($G$15*2.54))-450))),0))))))) | BO40: =IFERROR(__xludf.DUMMYFUNCTION("""COMPUTED_VALUE"""),"") | BP40: =if(BO40<>"",BO40,BP39) | BQ40: =IFERROR(__xludf.DUMMYFUNCTION("""COMPUTED_VALUE"""),"") | BS40: =if($G$13="Enable",if(BQ40<>"",BQ40,BR40),if(BR40<>"",BR40,BQ40)) | BT40: =if($BP40<>"",if(BS40<>"",BS40,BT39),"") | BU40: =if(BS40="",BU39,BT39) | BV40: =if($BP40<>"", if($G$9="Male", if(and($G$5="lb",$BT40<20),1, if(and($G$5="lb",$BT40>=20,$BT40<=25),0.8, if(and($G$5="lb",$BT40>25),0.73, if(and($G$5="kg",$BT40<20),2.2, if(and($G$5="kg",$BT40>=20,$BT40<=25),1.76, if(and($G$5="kg",$BT40>25),1.606)))))), if($G$9="Female", if(and($G$5="lb",$BT40<=25),1, if(and($G$5="lb",$BT40>25),0.8, if(and($G$5="kg",$BT40<=25),2.2, if(and($G$5="kg",$BT40>25),1.76,"")))),""))) -> FALSE | BW40: =if($BP40<>"",if(abs(($BP40*$BV40)-$BW39)>=5,$BP40*$BV40,$BW39),"") | BX40: =if($BP40<>"", if($G$9="Male", if(and($G$5="lb",$BT40<20),0.8, if(and($G$5="lb",$BT40>=20),0.73, if(and($G$5="kg",$BT40<20),1.76, if(and($G$5="kg",$BT40>=20),1.606)))), if($G$9="Female", if($G$5="lb",0.8,1.76),""))) -> FALSE | BY40: =if($BP40<>"", if($G$9="Male", if(and($G$5="lb",$BT40<20),1.2, if(and($G$5="lb",$BT40>=20),1, if(and($G$5="kg",$BT40<20),2.64, if(and($G$5="kg",$BT40>=20),2.2)))), if($G$9="Female", if($G$5="lb",1.4,3.08),""))) -> FALSE | BZ40: =if(BW40<>BW39,BP40*BX40,BZ39) -> 0 | CA40: =if(BW40<>BW39,BP40*BY40,CA39) -> 0
D41: =D39 -> Calories | L41: =if(counta(E41:K41)=0,"",AVERAGE(E41:K41)) | AB41: =B46 | AC41: =AB41 | AD41: =AC41+1 -> 1 | AE41: =AD41+1 -> 2 | AF41: =AE41+1 -> 3 | AG41: =AF41+1 -> 4 | AH41: =AG41+1 -> 5 | AI41: =AH41+1 -> 6 | AJ41: =AJ40+0.5 -> 3.5 | AL41: =COUNT(AP41:AV41) -> 0 | AM41: =AM40 | AP41: =IF(COUNT($E41:$K41)<1,"",IF(E41="",AQ35,E41)) | AQ41: =IF(F41="",AP41,F41) | AR41: =IF(G41="",AQ41,G41) | AS41: =IF(H41="",AR41,H41) | AT41: =IF(I41="",AS41,I41) | AU41: =IF(J41="",AT41,J41) | AV41: =IF(K41="",AU41,K41) | AW41: =IF(AL41=0,AW39,average(AP41:AV41)) | BO41: =IFERROR(__xludf.DUMMYFUNCTION("""COMPUTED_VALUE"""),"") | BP41: =if(BO41<>"",BO41,BP40) | BQ41: =IFERROR(__xludf.DUMMYFUNCTION("""COMPUTED_VALUE"""),"") | BS41: =if($G$13="Enable",if(BQ41<>"",BQ41,BR41),if(BR41<>"",BR41,BQ41)) | BT41: =if($BP41<>"",if(BS41<>"",BS41,BT40),"") | BU41: =if(BS41="",BU40,BT40) | BV41: =if($BP41<>"", if($G$9="Male", if(and($G$5="lb",$BT41<20),1, if(and($G$5="lb",$BT41>=20,$BT41<=25),0.8, if(and($G$5="lb",$BT41>25),0.73, if(and($G$5="kg",$BT41<20),2.2, if(and($G$5="kg",$BT41>=20,$BT41<=25),1.76, if(and($G$5="kg",$BT41>25),1.606)))))), if($G$9="Female", if(and($G$5="lb",$BT41<=25),1, if(and($G$5="lb",$BT41>25),0.8, if(and($G$5="kg",$BT41<=25),2.2, if(and($G$5="kg",$BT41>25),1.76,"")))),""))) -> FALSE | BW41: =if($BP41<>"",if(abs(($BP41*$BV41)-$BW40)>=5,$BP41*$BV41,$BW40),"") | BX41: =if($BP41<>"", if($G$9="Male", if(and($G$5="lb",$BT41<20),0.8, if(and($G$5="lb",$BT41>=20),0.73, if(and($G$5="kg",$BT41<20),1.76, if(and($G$5="kg",$BT41>=20),1.606)))), if($G$9="Female", if($G$5="lb",0.8,1.76),""))) -> FALSE | BY41: =if($BP41<>"", if($G$9="Male", if(and($G$5="lb",$BT41<20),1.2, if(and($G$5="lb",$BT41>=20),1, if(and($G$5="kg",$BT41<20),2.64, if(and($G$5="kg",$BT41>=20),2.2)))), if($G$9="Female", if($G$5="lb",1.4,3.08),""))) -> FALSE | BZ41: =if(BW41<>BW40,BP41*BX41,BZ40) -> 0 | CA41: =if(BW41<>BW40,BP41*BY41,CA40) -> 0
B42: =IF(B40="","",B40+7) | D42: =D40 -> Weight | L42: =if(counta(E42:K42)=0,"",AVERAGE(E42:K42)) | Q42: =BL42 | S42: =IFERROR(__xludf.DUMMYFUNCTION("IF(L42="""","""",(L42-index(filter($L$36:L40,$L$36:L40<>"""",ISEVEN(row($L$36:L40))),count(filter($L$36:L40,$L$36:L40<>"""",iseven(row($L$36:L40)))),1)))"),"") | U42: =if(BD$24=FALSE,"",IF(L42="","",BC42)) | W42: =IF(count(S42:S43)>1,1,0) -> 0 | X42: =if(Y42="","","Week 4") | Y42: =IF(S42="","",text(B42,"MMM-YY")) | AC42: =AB42 | AD42: =AC42+1 -> 1 | AE42: =AD42+1 -> 2 | AF42: =AE42+1 -> 3 | AG42: =AF42+1 -> 4 | AH42: =AG42+1 -> 5 | AI42: =AH42+1 -> 6 | AJ42: =AJ40+1 -> 4 | AK42: 3 | AL42: =COUNT(AP42:AV42) -> 0 | AM42: =IF(K42="",AM40,K42) | AP42: =IF(COUNT($E42:$K42)<1,"",IF(E42="",AQ36,E42)) | AQ42: =IF(F42="",AP42,F42) | AR42: =IF(G42="",AQ42,G42) | AS42: =IF(H42="",AR42,H42) | AT42: =IF(I42="",AS42,I42) | AU42: =IF(J42="",AT42,J42) | AV42: =IF(K42="",AU42,K42) | AW42: =IF(AL42=0,AW40,average(AP42:AV42)) | AX42: =if(AND(AW42=AX$34,$AL42>0),ROW(),0) -> 0 | AY42: =if(AND(AW42=AY$34,$AL42>0),ROW(),0) -> 0 | AZ42: =IF(AW42="","",AW42-AW40) | BA42: =if(BB42>0,row(),0) -> 42 | BB42: =max(if(E42=AW$30,COLUMN(E42),0),if(F42=AW$30,COLUMN(F42),0),if(G42=AW$30,COLUMN(G42),0),if(H42=AW$30,COLUMN(H42),0),if(I42=AW$30,COLUMN(I42),0),if(J42=AW$30,COLUMN(J42),0),if(K42=AW$30,COLUMN(K42),0)) -> 11 | BC42: =IF(BD42="","",IF(AZ42="","",BD42)) | BD42: =IF(AL42=0,BD40,IF(AL43=0,BD40,((AW43+(((-AZ42)*$BD$7)/AL43)+sum($BE$38:BE40))/AK42))) -> 0 | BE42: =IF(AL42=0,BE40,IF(AL43=0,BE40,AW43+(((-AZ42)*$BD$7)/AL43))) -> 0 | BJ42: =text(B42,"YYYY MMM") | BL42: =if($G$13="Disable","", if($G$9="","",if(and($G$9="Male",count($N42:$O42)<>2),"", if(and($G$9="Male",count($N42:$O42)=2),round(if($N42="","", if($G$14="cm",86.01*log($N42-$O42)-70.041*log($G$15)+30.3, if($G$14="inch",86.01*log(($N42-$O42)*2.54)-70.041*log($G$15*2.54)+30.3))),0), if(and($G$9="Female",count($N42:$P42)<>3),"", if(and($G$9="Female",count($N42:$P42)=3),round(if($N42="","", if($G$14="cm",495/(1.29579-0.35004*log10($N42+$P42-$O42)+0.221 * log10($G$15))-450, if($G$14="inch",495/(1.29579-0.35004*log10(($N42+$P42-$O42)*2.54)+0.221 * log10($G$15*2.54))-450))),0))))))) | BO42: =IFERROR(__xludf.DUMMYFUNCTION("""COMPUTED_VALUE"""),"") | BP42: =if(BO42<>"",BO42,BP41) | BQ42: =IFERROR(__xludf.DUMMYFUNCTION("""COMPUTED_VALUE"""),"") | BS42: =if($G$13="Enable",if(BQ42<>"",BQ42,BR42),if(BR42<>"",BR42,BQ42)) | BT42: =if($BP42<>"",if(BS42<>"",BS42,BT41),"") | BU42: =if(BS42="",BU41,BT41) | BV42: =if($BP42<>"", if($G$9="Male", if(and($G$5="lb",$BT42<20),1, if(and($G$5="lb",$BT42>=20,$BT42<=25),0.8, if(and($G$5="lb",$BT42>25),0.73, if(and($G$5="kg",$BT42<20),2.2, if(and($G$5="kg",$BT42>=20,$BT42<=25),1.76, if(and($G$5="kg",$BT42>25),1.606)))))), if($G$9="Female", if(and($G$5="lb",$BT42<=25),1, if(and($G$5="lb",$BT42>25),0.8, if(and($G$5="kg",$BT42<=25),2.2, if(and($G$5="kg",$BT42>25),1.76,"")))),""))) -> FALSE | BW42: =if($BP42<>"",if(abs(($BP42*$BV42)-$BW41)>=5,$BP42*$BV42,$BW41),"") | BX42: =if($BP42<>"", if($G$9="Male", if(and($G$5="lb",$BT42<20),0.8, if(and($G$5="lb",$BT42>=20),0.73, if(and($G$5="kg",$BT42<20),1.76, if(and($G$5="kg",$BT42>=20),1.606)))), if($G$9="Female", if($G$5="lb",0.8,1.76),""))) -> FALSE | BY42: =if($BP42<>"", if($G$9="Male", if(and($G$5="lb",$BT42<20),1.2, if(and($G$5="lb",$BT42>=20),1, if(and($G$5="kg",$BT42<20),2.64, if(and($G$5="kg",$BT42>=20),2.2)))), if($G$9="Female", if($G$5="lb",1.4,3.08),""))) -> FALSE | BZ42: =if(BW42<>BW41,BP42*BX42,BZ41) -> 0 | CA42: =if(BW42<>BW41,BP42*BY42,CA41) -> 0
...

Sheet SUMMARY
B2: Summary
M4: Week | N4: =concatenate("Average weight/",CALCULATIONS!H7) -> Average weight/ | O4: Average TDEE | Q4: Month | R4: Actual Weight Change | S4: Goal Weight Change
M5: =IFERROR(__xludf.DUMMYFUNCTION("iferror(filter(CALCULATIONS!$B$36:$B140,CALCULATIONS!$L$36:$L140<>"""",ISEVEN(row(CALCULATIONS!$L$36:$L140))),"""")"),"") | N5: =if(M5="","",round(vlookup(M5,CALCULATIONS!$B$36:$L$141,11,0),2)) | O5: {=if(M5="","",index(CALCULATIONS!$B$36:$L$141,match($M5,CALCULATIONS!$B$36:$B$141,0)+1,11))} | Q5: =IFERROR(__xludf.DUMMYFUNCTION("iferror(unique(filter(CALCULATIONS!Y36:Y141,CALCULATIONS!Y36:Y141<>"""")),"""")"),"") | R5: =if(Q5="","",sumif(CALCULATIONS!$Y$36:$Y141,$Q5,CALCULATIONS!$S$36:$S141)) | S5: =if(Q5="","",(CALCULATIONS!$AW$15*4)*1)
N6: =if(M6="","",round(vlookup(M6,CALCULATIONS!$B$36:$L$141,11,0),2)) | O6: {=if(M6="","",index(CALCULATIONS!$B$36:$L$141,match($M6,CALCULATIONS!$B$36:$B$141,0)+1,11))} | R6: =if(Q6="","",sumif(CALCULATIONS!$Y$36:$Y142,$Q6,CALCULATIONS!$S$36:$S142)) | S6: =if(Q6="","",(CALCULATIONS!$AW$15*4)*1)
N7: =if(M7="","",round(vlookup(M7,CALCULATIONS!$B$36:$L$141,11,0),2)) | O7: {=if(M7="","",index(CALCULATIONS!$B$36:$L$141,match($M7,CALCULATIONS!$B$36:$B$141,0)+1,11))} | R7: =if(Q7="","",sumif(CALCULATIONS!$Y$36:$Y143,$Q7,CALCULATIONS!$S$36:$S143)) | S7: =if(Q7="","",(CALCULATIONS!$AW$15*4)*1)
N8: =if(M8="","",round(vlookup(M8,CALCULATIONS!$B$36:$L$141,11,0),2)) | O8: {=if(M8="","",index(CALCULATIONS!$B$36:$L$141,match($M8,CALCULATIONS!$B$36:$B$141,0)+1,11))} | R8: =if(Q8="","",sumif(CALCULATIONS!$Y$36:$Y144,$Q8,CALCULATIONS!$S$36:$S144)) | S8: =if(Q8="","",(CALCULATIONS!$AW$15*4)*1)
N9: =if(M9="","",round(vlookup(M9,CALCULATIONS!$B$36:$L$141,11,0),2)) | O9: {=if(M9="","",index(CALCULATIONS!$B$36:$L$141,match($M9,CALCULATIONS!$B$36:$B$141,0)+1,11))} | R9: =if(Q9="","",sumif(CALCULATIONS!$Y$36:$Y145,$Q9,CALCULATIONS!$S$36:$S145)) | S9: =if(Q9="","",(CALCULATIONS!$AW$15*4)*1)
N10: =if(M10="","",round(vlookup(M10,CALCULATIONS!$B$36:$L$141,11,0),2)) | O10: {=if(M10="","",index(CALCULATIONS!$B$36:$L$141,match($M10,CALCULATIONS!$B$36:$B$141,0)+1,11))} | R10: =if(Q10="","",sumif(CALCULATIONS!$Y$36:$Y146,$Q10,CALCULATIONS!$S$36:$S146)) | S10: =if(Q10="","",(CALCULATIONS!$AW$15*4)*1)
N11: =if(M11="","",round(vlookup(M11,CALCULATIONS!$B$36:$L$141,11,0),2)) | O11: {=if(M11="","",index(CALCULATIONS!$B$36:$L$141,match($M11,CALCULATIONS!$B$36:$B$141,0)+1,11))} | R11: =if(Q11="","",sumif(CALCULATIONS!$Y$36:$Y147,$Q11,CALCULATIONS!$S$36:$S147)) | S11: =if(Q11="","",(CALCULATIONS!$AW$15*4)*1)
N12: =if(M12="","",round(vlookup(M12,CALCULATIONS!$B$36:$L$141,11,0),2)) | O12: {=if(M12="","",index(CALCULATIONS!$B$36:$L$141,match($M12,CALCULATIONS!$B$36:$B$141,0)+1,11))} | R12: =if(Q12="","",sumif(CALCULATIONS!$Y$36:$Y148,$Q12,CALCULATIONS!$S$36:$S148)) | S12: =if(Q12="","",(CALCULATIONS!$AW$15*4)*1)
N13: =if(M13="","",round(vlookup(M13,CALCULATIONS!$B$36:$L$141,11,0),2)) | O13: {=if(M13="","",index(CALCULATIONS!$B$36:$L$141,match($M13,CALCULATIONS!$B$36:$B$141,0)+1,11))} | R13: =if(Q13="","",sumif(CALCULATIONS!$Y$36:$Y149,$Q13,CALCULATIONS!$S$36:$S149)) | S13: =if(Q13="","",(CALCULATIONS!$AW$15*4)*1)
N14: =if(M14="","",round(vlookup(M14,CALCULATIONS!$B$36:$L$141,11,0),2)) | O14: {=if(M14="","",index(CALCULATIONS!$B$36:$L$141,match($M14,CALCULATIONS!$B$36:$B$141,0)+1,11))} | R14: =if(Q14="","",sumif(CALCULATIONS!$Y$36:$Y150,$Q14,CALCULATIONS!$S$36:$S150)) | S14: =if(Q14="","",(CALCULATIONS!$AW$15*4)*1)
N15: =if(M15="","",round(vlookup(M15,CALCULATIONS!$B$36:$L$141,11,0),2)) | O15: {=if(M15="","",index(CALCULATIONS!$B$36:$L$141,match($M15,CALCULATIONS!$B$36:$B$141,0)+1,11))} | R15: =if(Q15="","",sumif(CALCULATIONS!$Y$36:$Y151,$Q15,CALCULATIONS!$S$36:$S151)) | S15: =if(Q15="","",(CALCULATIONS!$AW$15*4)*1)
N16: =if(M16="","",round(vlookup(M16,CALCULATIONS!$B$36:$L$141,11,0),2)) | O16: {=if(M16="","",index(CALCULATIONS!$B$36:$L$141,match($M16,CALCULATIONS!$B$36:$B$141,0)+1,11))} | R16: =if(Q16="","",sumif(CALCULATIONS!$Y$36:$Y152,$Q16,CALCULATIONS!$S$36:$S152)) | S16: =if(Q16="","",(CALCULATIONS!$AW$15*4)*1)
N17: =if(M17="","",round(vlookup(M17,CALCULATIONS!$B$36:$L$141,11,0),2)) | O17: {=if(M17="","",index(CALCULATIONS!$B$36:$L$141,match($M17,CALCULATIONS!$B$36:$B$141,0)+1,11))} | R17: =if(Q17="","",sumif(CALCULATIONS!$Y$36:$Y153,$Q17,CALCULATIONS!$S$36:$S153)) | S17: =if(Q17="","",(CALCULATIONS!$AW$15*4)*1)
N18: =if(M18="","",round(vlookup(M18,CALCULATIONS!$B$36:$L$141,11,0),2)) | O18: {=if(M18="","",index(CALCULATIONS!$B$36:$L$141,match($M18,CALCULATIONS!$B$36:$B$141,0)+1,11))} | R18: =if(Q18="","",sumif(CALCULATIONS!$Y$36:$Y154,$Q18,CALCULATIONS!$S$36:$S154)) | S18: =if(Q18="","",(CALCULATIONS!$AW$15*4)*1)
N19: =if(M19="","",round(vlookup(M19,CALCULATIONS!$B$36:$L$141,11,0),2)) | O19: {=if(M19="","",index(CALCULATIONS!$B$36:$L$141,match($M19,CALCULATIONS!$B$36:$B$141,0)+1,11))}
N20: =if(M20="","",round(vlookup(M20,CALCULATIONS!$B$36:$L$141,11,0),2)) | O20: {=if(M20="","",index(CALCULATIONS!$B$36:$L$141,match($M20,CALCULATIONS!$B$36:$B$141,0)+1,11))}
N21: =if(M21="","",round(vlookup(M21,CALCULATIONS!$B$36:$L$141,11,0),2)) | O21: {=if(M21="","",index(CALCULATIONS!$B$36:$L$141,match($M21,CALCULATIONS!$B$36:$B$141,0)+1,11))}
N22: =if(M22="","",round(vlookup(M22,CALCULATIONS!$B$36:$L$141,11,0),2)) | O22: {=if(M22="","",index(CALCULATIONS!$B$36:$L$141,match($M22,CALCULATIONS!$B$36:$B$141,0)+1,11))}
N23: =if(M23="","",round(vlookup(M23,CALCULATIONS!$B$36:$L$141,11,0),2)) | O23: {=if(M23="","",index(CALCULATIONS!$B$36:$L$141,match($M23,CALCULATIONS!$B$36:$B$141,0)+1,11))}
N24: =if(M24="","",round(vlookup(M24,CALCULATIONS!$B$36:$L$141,11,0),2)) | O24: {=if(M24="","",index(CALCULATIONS!$B$36:$L$141,match($M24,CALCULATIONS!$B$36:$B$141,0)+1,11))}
N25: =if(M25="","",round(vlookup(M25,CALCULATIONS!$B$36:$L$141,11,0),2)) | O25: {=if(M25="","",index(CALCULATIONS!$B$36:$L$141,match($M25,CALCULATIONS!$B$36:$B$141,0)+1,11))}
N26: =if(M26="","",round(vlookup(M26,CALCULATIONS!$B$36:$L$141,11,0),2)) | O26: {=if(M26="","",index(CALCULATIONS!$B$36:$L$141,match($M26,CALCULATIONS!$B$36:$B$141,0)+1,11))}
N27: =if(M27="","",round(vlookup(M27,CALCULATIONS!$B$36:$L$141,11,0),2)) | O27: {=if(M27="","",index(CALCULATIONS!$B$36:$L$141,match($M27,CALCULATIONS!$B$36:$B$141,0)+1,11))}
N28: =if(M28="","",round(vlookup(M28,CALCULATIONS!$B$36:$L$141,11,0),2)) | O28: {=if(M28="","",index(CALCULATIONS!$B$36:$L$141,match($M28,CALCULATIONS!$B$36:$B$141,0)+1,11))}
N29: =if(M29="","",round(vlookup(M29,CALCULATIONS!$B$36:$L$141,11,0),2)) | O29: {=if(M29="","",index(CALCULATIONS!$B$36:$L$141,match($M29,CALCULATIONS!$B$36:$B$141,0)+1,11))}
N30: =if(M30="","",round(vlookup(M30,CALCULATIONS!$B$36:$L$141,11,0),2)) | O30: {=if(M30="","",index(CALCULATIONS!$B$36:$L$141,match($M30,CALCULATIONS!$B$36:$B$141,0)+1,11))}
... N57: =if(M57="","",round(vlookup(M57,CALCULATIONS!$B$36:$L$141,11,0),2)) | O57: {=if(M57="","",index(CALCULATIONS!$B$36:$L$141,match($M57,CALCULATIONS!$B$36:$B$141,0)+1,11))}

Sheet FAQ
B2: Frequently Asked Questions
B4: Do I need to factor in or eat back my “calories burned” through activity? NO! The sheet averages your activity level (along with all other factors) such that you don’t need to worry about tracking or eating back your additional calories burned through exercise. Instead, simply stick to the calories/macros shown within your sheet. When will my spreadsheet start adjusting my initial calories/macros and how often should I change to the new recommendations? The sheet will start tweaking your recommendations after you finish logging the first day of week 4. Prior to this, it will only show your initial calorie/macro recommendations. This is done so that you stick to the initial values and then adjust to the more accurate values it provides in the 4th week since it has now has had sufficient data to work with. And from then on, the sheet will continue to adjust weekly. As for how often to change to the new recommendations, every 3-4 weeks is a good idea to prevent you from reaching plateaus – but I’d suggest following the advice provided within the program regarding that. In the step 1 table, do I need to change my starting weight or body fat percentage as I gain/lose weight? No. As discussed in the tutorials, if you’re updating your daily bodyweight and occasionally updating your body fat in the step 4 table, then the sheet will detect this and make the necessary adjustments. The body fat calculation doesn’t seem accurate for my body. Should I still use it? The body fat calculator uses something called the “US Navy Method”. For many people it’s quite accurate (with some error of course) whereas for others it can be totally off – which is expected since its based on bodily measurements that can have a lot of variation and throw off the calculation. So use your own judgement - if the estimated % seems way off for you, then use the other method of estimating your body fat by looking at the body fat chat provided. Regardless, this will only affect your initial calorie/macro recommendations. Also make sure you’re taking the measurements properly by reading how in the written up tutorials. My nutrition spreadsheet has updated the calories/macros but it seems WAY off (the calories are either way too high or way too low). Is something wrong? If you’re losing or gaining weight too quickly or too slowly based on your weekly goal, then the sheet will adjust its recommendations accordingly. However, there are several variables that can potentially throw this off. One variable is that you are not tracking accurately! You input that you’re eating 2,000 calories yet in reality you’re eating 2,500 calories and that’s why you’re not losing weight. Make sure this isn’t the problem. On the other hand, if you’re losing weight, then the sheet does not account for possible muscle growth as you lose weight (body recomposition). So if you lost 3 lbs of fat yet gained 1 lb of muscle in the process, then the sheet would only think you lost 2 lbs. This can make the sheet “think” that you aren’t hitting your weight loss goal, but in reality, you’re just building muscle as you lose fat which is a good thing! In this case, we suggest ignoring the sheet’s adjustments and stick to what has been working. If you are visually looking better AND you’re getting stronger in the gym then ignore what’s happening with your bodyweight! Your bodyweight is just one way to assess your progress but is not end all be all. You can be making tons of progress without seeing much change in your weight – so take frequent pictures, focus on progressing in the gym, and take bodily measurements in order to provide you with the most information possible! For this reason, we’ve set a “floor” for the sheet to not go below 1,500 calories for males and 1,200 calories for females. If you’ve reached this floor, then you are likely going through a body recomposition and should not continue decreasing your calories. This low of a calorie intake would only be appropriate for smaller/lighter/shorter individuals. Also keep in mind that the sheet often just needs more data – as it gets more and more accurate with the more data it has. So be patient, keep logging, and use your own judgement! Understand what the spreadsheet does and how it works, and you’ll be able to use maximize its effectiveness! If I change my goal/phase (e.g. lose fat to build muscle), do I need to start a new sheet? Nope! The beauty about the sheet is that it will “remember” your data and use it to provide the best recommendations for you regardless of what your chosen goal/phase is.

Sheet Workout A (Phase 1)
A1: Workout
A2: A | B2: R | C2: W | D2: R | E2: W | F2: R | G2: W | H2: R | I2: W | J2: R | K2: W | L2: R | M2: W | N2: R | O2: W | P2: R | Q2: W | R2: R | S2: W | T2: R | U2: W | V2: R | W2: W | X2: R | Y2: W | Z2: R | AA2: W | AB2: R | AC2: W | AD2: R | AE2: W | AF2: R | AG2: W | AH2: R | AI2: W | AJ2: R | AK2: W | AL2: R | AM2: W | AN2: R | AO2: W | AP2: R | AQ2: W | AR2: R | AS2: W | AT2: R | AU2: W | AV2: R | AW2: W | AX2: R | AY2: W | AZ2: R | BA2: W | BB2: R | BC2: W | BD2: R | BE2: W | BF2: R | BG2: W | BH2: R | BI2: W | BJ2: R | BK2: W | BL2: R | BM2: W | BN2: R | BO2: W | BP2: R | BQ2: W | BR2: R | BS2: W | BT2: R | BU2: W | BV2: R | BW2: W | BX2: R | BY2: W | BZ2: R | CA2: W | CB2: R | CC2: W | CD2: R | CE2: W | CF2: R | CG2: W | CH2: R | CI2: W | CJ2: R | CK2: W | CL2: R | CM2: W | CN2: R | CO2: W | CP2: R | CQ2: W | CR2: R | CS2: W | CT2: R | CU2: W | CV2: R | CW2: W | CX2: R | CY2: W | CZ2: R | DA2: W | DB2: R | DC2: W | DD2: R | DE2: W | DF2: R | DG2: W | DH2: R | DI2: W | DJ2: R | DK2: W | DL2: R | DM2: W | DN2: R | DO2: W | DP2: R | DQ2: W | DR2: R | DS2: W | DT2: R | DU2: W | DV2: R | DW2: W | DX2: R | DY2: W | DZ2: R | EA2: W | EB2: R | EC2: W | ED2: R | EE2: W | EF2: R | EG2: W | EH2: R | EI2: W | EJ2: R | EK2: W | EL2: R | EM2: W | EN2: R | EO2: W | EP2: R | EQ2: W | ER2: R | ES2: W | ET2: R | EU2: W | EV2: R | EW2: W | EX2: R | EY2: W | EZ2: R | FA2: W | FB2: R | FC2: W | FD2: R | FE2: W | FF2: R | FG2: W | FH2: R | FI2: W | FJ2: R | FK2: W | FL2: R | FM2: W | FN2: R | FO2: W | FP2: R | FQ2: W | FR2: R | FS2: W | FT2: R | FU2: W | FV2: R | FW2: W | FX2: R | FY2: W | FZ2: R | GA2: W | GB2: R | GC2: W | GD2: R | GE2: W | GF2: R | GG2: W | GH2: R | GI2: W | GJ2: R | GK2: W | GL2: R | GM2: W | GN2: R | GO2: W | GP2: R | GQ2: W | GR2: R | GS2: W
A3: Barbell Bench Press
A4: SET 1: 8-10
A5: SET 2: 8-10
A6: SET 3: 8-10
A7: Back Squat
A8: SET 1: 8-10
A9: SET 2: 8-10
A10: SET 3: 8-10
A11: SET 4: 8-10
A12: Chest-Supported Row
A13: SET 1: 8-10
A14: SET 2: 8-10
... A24: SET 4: 6-10

Sheet Workout B (Phase 1)
A1: Workout
A2: B | B2: R | C2: W | D2: R | E2: W | F2: R | G2: W | H2: R | I2: W | J2: R | K2: W | L2: R | M2: W | N2: R | O2: W | P2: R | Q2: W | R2: R | S2: W | T2: R | U2: W | V2: R | W2: W | X2: R | Y2: W | Z2: R | AA2: W | AB2: R | AC2: W | AD2: R | AE2: W | AF2: R | AG2: W | AH2: R | AI2: W | AJ2: R | AK2: W | AL2: R | AM2: W | AN2: R | AO2: W | AP2: R | AQ2: W | AR2: R | AS2: W | AT2: R | AU2: W | AV2: R | AW2: W | AX2: R | AY2: W | AZ2: R | BA2: W | BB2: R | BC2: W | BD2: R | BE2: W | BF2: R | BG2: W | BH2: R | BI2: W | BJ2: R | BK2: W | BL2: R | BM2: W | BN2: R | BO2: W | BP2: R | BQ2: W | BR2: R | BS2: W | BT2: R | BU2: W | BV2: R | BW2: W | BX2: R | BY2: W | BZ2: R | CA2: W | CB2: R | CC2: W | CD2: R | CE2: W | CF2: R | CG2: W | CH2: R | CI2: W | CJ2: R | CK2: W | CL2: R | CM2: W | CN2: R | CO2: W | CP2: R | CQ2: W | CR2: R | CS2: W | CT2: R | CU2: W | CV2: R | CW2: W | CX2: R | CY2: W | CZ2: R | DA2: W | DB2: R | DC2: W | DD2: R | DE2: W | DF2: R | DG2: W | DH2: R | DI2: W | DJ2: R | DK2: W | DL2: R | DM2: W | DN2: R | DO2: W | DP2: R | DQ2: W | DR2: R | DS2: W | DT2: R | DU2: W | DV2: R | DW2: W | DX2: R | DY2: W | DZ2: R | EA2: W | EB2: R | EC2: W | ED2: R | EE2: W | EF2: R | EG2: W | EH2: R | EI2: W | EJ2: R | EK2: W | EL2: R | EM2: W | EN2: R | EO2: W | EP2: R | EQ2: W | ER2: R | ES2: W | ET2: R | EU2: W | EV2: R | EW2: W | EX2: R | EY2: W | EZ2: R | FA2: W | FB2: R | FC2: W | FD2: R | FE2: W | FF2: R | FG2: W | FH2: R | FI2: W | FJ2: R | FK2: W | FL2: R | FM2: W | FN2: R | FO2: W | FP2: R | FQ2: W | FR2: R | FS2: W | FT2: R | FU2: W | FV2: R | FW2: W | FX2: R | FY2: W | FZ2: R | GA2: W | GB2: R | GC2: W | GD2: R | GE2: W | GF2: R | GG2: W | GH2: R | GI2: W | GJ2: R | GK2: W | GL2: R | GM2: W | GN2: R | GO2: W | GP2: R | GQ2: W | GR2: R | GS2: W
A3: Incline Dumbbell Press
A4: SET 1: 10-12
A5: SET 2: 10-12
A6: SET 3: 10-12
A7: Deadlift
A8: SET 1: 6-8
A9: SET 2: 6-8
A10: SET 3: 6-8
A11: Standing Overhead Press
A12: SET 1: 8-10
A13: SET 2: 8-10
A14: SET 3: 8-10
... A23: SET 4: 10-15

Sheet Upper Body 1 (Phase 2)
A1: Upper Body 1
B2: R | C2: W | D2: R | E2: W | F2: R | G2: W | H2: R | I2: W | J2: R | K2: W | L2: R | M2: W | N2: R | O2: W | P2: R | Q2: W | R2: R | S2: W | T2: R | U2: W | V2: R | W2: W | X2: R | Y2: W | Z2: R | AA2: W | AB2: R | AC2: W | AD2: R | AE2: W | AF2: R | AG2: W | AH2: R | AI2: W | AJ2: R | AK2: W | AL2: R | AM2: W | AN2: R | AO2: W | AP2: R | AQ2: W | AR2: R | AS2: W | AT2: R | AU2: W | AV2: R | AW2: W | AX2: R | AY2: W | AZ2: R | BA2: W | BB2: R | BC2: W | BD2: R | BE2: W | BF2: R | BG2: W | BH2: R | BI2: W | BJ2: R | BK2: W | BL2: R | BM2: W | BN2: R | BO2: W | BP2: R | BQ2: W | BR2: R | BS2: W | BT2: R | BU2: W | BV2: R | BW2: W | BX2: R | BY2: W | BZ2: R | CA2: W | CB2: R | CC2: W | CD2: R | CE2: W | CF2: R | CG2: W | CH2: R | CI2: W | CJ2: R | CK2: W | CL2: R | CM2: W | CN2: R | CO2: W | CP2: R | CQ2: W | CR2: R | CS2: W | CT2: R | CU2: W | CV2: R | CW2: W | CX2: R | CY2: W | CZ2: R | DA2: W | DB2: R | DC2: W | DD2: R | DE2: W | DF2: R | DG2: W | DH2: R | DI2: W | DJ2: R | DK2: W | DL2: R | DM2: W | DN2: R | DO2: W | DP2: R | DQ2: W | DR2: R | DS2: W | DT2: R | DU2: W | DV2: R | DW2: W | DX2: R | DY2: W | DZ2: R | EA2: W | EB2: R | EC2: W | ED2: R | EE2: W | EF2: R | EG2: W | EH2: R | EI2: W | EJ2: R | EK2: W | EL2: R | EM2: W | EN2: R | EO2: W | EP2: R | EQ2: W | ER2: R | ES2: W | ET2: R | EU2: W | EV2: R | EW2: W | EX2: R | EY2: W | EZ2: R | FA2: W | FB2: R | FC2: W | FD2: R | FE2: W | FF2: R | FG2: W | FH2: R | FI2: W | FJ2: R | FK2: W | FL2: R | FM2: W | FN2: R | FO2: W | FP2: R | FQ2: W | FR2: R | FS2: W | FT2: R | FU2: W | FV2: R | FW2: W | FX2: R | FY2: W | FZ2: R | GA2: W | GB2: R | GC2: W | GD2: R | GE2: W | GF2: R | GG2: W | GH2: R | GI2: W | GJ2: R | GK2: W | GL2: R | GM2: W | GN2: R | GO2: W | GP2: R | GQ2: W | GR2: R | GS2: W
A3: Incline Dumbbell Press
A4: SET 1: 8-10
A5: SET 2: 8-10
A6: SET 3: 8-10
A7: SET 4: 8-10
A8: Chest-Supported Row
A9: SET 1: 8-10
A10: SET 2: 8-10
A11: SET 3: 8-10
A12: Lean-Away Cable Lateral Raises
A13: SET 1: 10-12
A14: SET 2: 10-12
... A23: SET 3: 12-15

Sheet Lower Body 1 (Phase 2)
A1: Lower Body 1
B2: R | C2: W | D2: R | E2: W | F2: R | G2: W | H2: R | I2: W | J2: R | K2: W | L2: R | M2: W | N2: R | O2: W | P2: R | Q2: W | R2: R | S2: W | T2: R | U2: W | V2: R | W2: W | X2: R | Y2: W | Z2: R | AA2: W | AB2: R | AC2: W | AD2: R | AE2: W | AF2: R | AG2: W | AH2: R | AI2: W | AJ2: R | AK2: W | AL2: R | AM2: W | AN2: R | AO2: W | AP2: R | AQ2: W | AR2: R | AS2: W | AT2: R | AU2: W | AV2: R | AW2: W | AX2: R | AY2: W | AZ2: R | BA2: W | BB2: R | BC2: W | BD2: R | BE2: W | BF2: R | BG2: W | BH2: R | BI2: W | BJ2: R | BK2: W | BL2: R | BM2: W | BN2: R | BO2: W | BP2: R | BQ2: W | BR2: R | BS2: W | BT2: R | BU2: W | BV2: R | BW2: W | BX2: R | BY2: W | BZ2: R | CA2: W | CB2: R | CC2: W | CD2: R | CE2: W | CF2: R | CG2: W | CH2: R | CI2: W | CJ2: R | CK2: W | CL2: R | CM2: W | CN2: R | CO2: W | CP2: R | CQ2: W | CR2: R | CS2: W | CT2: R | CU2: W | CV2: R | CW2: W | CX2: R | CY2: W | CZ2: R | DA2: W | DB2: R | DC2: W | DD2: R | DE2: W | DF2: R | DG2: W | DH2: R | DI2: W | DJ2: R | DK2: W | DL2: R | DM2: W | DN2: R | DO2: W | DP2: R | DQ2: W | DR2: R | DS2: W | DT2: R | DU2: W | DV2: R | DW2: W | DX2: R | DY2: W | DZ2: R | EA2: W | EB2: R | EC2: W | ED2: R | EE2: W | EF2: R | EG2: W | EH2: R | EI2: W | EJ2: R | EK2: W | EL2: R | EM2: W | EN2: R | EO2: W | EP2: R | EQ2: W | ER2: R | ES2: W | ET2: R | EU2: W | EV2: R | EW2: W | EX2: R | EY2: W | EZ2: R | FA2: W | FB2: R | FC2: W | FD2: R | FE2: W | FF2: R | FG2: W | FH2: R | FI2: W | FJ2: R | FK2: W | FL2: R | FM2: W | FN2: R | FO2: W | FP2: R | FQ2: W | FR2: R | FS2: W | FT2: R | FU2: W | FV2: R | FW2: W | FX2: R | FY2: W | FZ2: R | GA2: W | GB2: R | GC2: W | GD2: R | GE2: W | GF2: R | GG2: W | GH2: R | GI2: W | GJ2: R | GK2: W | GL2: R | GM2: W | GN2: R | GO2: W | GP2: R | GQ2: W | GR2: R | GS2: W
A3: Back Squat
A4: SET 1: 6-8
A5: SET 2: 6-8
A6: SET 3: 6-8
A7: SET 4: 6-8
A8: Bulgarian Split Squat
A9: SET 1: 8-10
A10: SET 2: 8-10
A11: SET 3: 8-10
A12: Swiss Ball Leg Curls
A13: SET 1: 8-12
A14: SET 2: 8-12
... A21: SET 4: 6-10

Sheet  Upper Body 2 (Phase 2)
A1: Upper Body 2
B2: R | C2: W | D2: R | E2: W | F2: R | G2: W | H2: R | I2: W | J2: R | K2: W | L2: R | M2: W | N2: R | O2: W | P2: R | Q2: W | R2: R | S2: W | T2: R | U2: W | V2: R | W2: W | X2: R | Y2: W | Z2: R | AA2: W | AB2: R | AC2: W | AD2: R | AE2: W | AF2: R | AG2: W | AH2: R | AI2: W | AJ2: R | AK2: W | AL2: R | AM2: W | AN2: R | AO2: W | AP2: R | AQ2: W | AR2: R | AS2: W | AT2: R | AU2: W | AV2: R | AW2: W | AX2: R | AY2: W | AZ2: R | BA2: W | BB2: R | BC2: W | BD2: R | BE2: W | BF2: R | BG2: W | BH2: R | BI2: W | BJ2: R | BK2: W | BL2: R | BM2: W | BN2: R | BO2: W | BP2: R | BQ2: W | BR2: R | BS2: W | BT2: R | BU2: W | BV2: R | BW2: W | BX2: R | BY2: W | BZ2: R | CA2: W | CB2: R | CC2: W | CD2: R | CE2: W | CF2: R | CG2: W | CH2: R | CI2: W | CJ2: R | CK2: W | CL2: R | CM2: W | CN2: R | CO2: W | CP2: R | CQ2: W | CR2: R | CS2: W | CT2: R | CU2: W | CV2: R | CW2: W | CX2: R | CY2: W | CZ2: R | DA2: W | DB2: R | DC2: W | DD2: R | DE2: W | DF2: R | DG2: W | DH2: R | DI2: W | DJ2: R | DK2: W | DL2: R | DM2: W | DN2: R | DO2: W | DP2: R | DQ2: W | DR2: R | DS2: W | DT2: R | DU2: W | DV2: R | DW2: W | DX2: R | DY2: W | DZ2: R | EA2: W | EB2: R | EC2: W | ED2: R | EE2: W | EF2: R | EG2: W | EH2: R | EI2: W | EJ2: R | EK2: W | EL2: R | EM2: W | EN2: R | EO2: W | EP2: R | EQ2: W | ER2: R | ES2: W | ET2: R | EU2: W | EV2: R | EW2: W | EX2: R | EY2: W | EZ2: R | FA2: W | FB2: R | FC2: W | FD2: R | FE2: W | FF2: R | FG2: W | FH2: R | FI2: W | FJ2: R | FK2: W | FL2: R | FM2: W | FN2: R | FO2: W | FP2: R | FQ2: W | FR2: R | FS2: W | FT2: R | FU2: W | FV2: R | FW2: W | FX2: R | FY2: W | FZ2: R | GA2: W | GB2: R | GC2: W | GD2: R | GE2: W | GF2: R | GG2: W | GH2: R | GI2: W | GJ2: R | GK2: W | GL2: R | GM2: W | GN2: R | GO2: W | GP2: R | GQ2: W | GR2: R | GS2: W
A3: Barbell Bench Press
A4: SET 1: 6-8
A5: SET 2: 6-8
A6: SET 3: 6-8
A7: SET 4: 6-8
A8: Seated Row
A9: SET 1: 8-10
A10: SET 2: 8-10
A11: SET 3: 8-10
A12: Standing Overhead Press
A13: SET 1: 8-10
A14: SET 2: 8-10
... A28: SET 3: 8-10

Sheet Lower Body 2 (Phase 2)
A1: Lower Body 2
